Workbook

Sheet Booking_Services_Clean
A1: booking_service_id | B1: booking_id | C1: service_id | D1: quantity
A2: 1 | B2: 1 | C2: 1 | D2: 2
A3: 2 | B3: 1 | C3: 4 | D3: 1
A4: 3 | B4: 2 | C4: 2 | D4: 2
A5: 4 | B5: 2 | C5: 3 | D5: 2
A6: 5 | B6: 3 | C6: 1 | D6: 1
A7: 6 | B7: 4 | C7: 5 | D7: 2
A8: 7 | B8: 4 | C8: 7 | D8: 1
A9: 8 | B9: 5 | C9: 6 | D9: 1
A10: 9 | B10: 6 | C10: 8 | D10: 2
A11: 10 | B11: 8 | C11: 9 | D11: 1
A12: 11 | B12: 9 | C12: 10 | D12: 2
A13: 12 | B13: 10 | C13: 3 | D13: 3
... A201: 200 | B201: 60 | C201: 21 | D201: 3

Sheet Formula_Practice_Log
A1: Sr. No. | B1: Formula Name | C1: Category | D1: Purpose | E1: Applied In
A2: 1 | B2: SUM | C2: Math & Statistical | D2: Calculates the total of numeric values | E2: Rooms_Clean
A3: 2 | B3: COUNT | C3: Math & Statistical | D3: Counts cells containing numeric values | E3: Rooms_Clean
A4: 3 | B4: AVERAGE | C4: Math & Statistical | D4: Calculates the average of numeric values | E4: Rooms_Clean
A5: 4 | B5: COUNTIF | C5: Logical | D5: Counts cells that meet one condition | E5: Rooms_Clean
A6: 5 | B6: SUMIF | C6: Math & Statistical | D6: Adds values that meet one condition | E6: Rooms_Clean
A7: 6 | B7: AVERAGEIF | C7: Math & Statistical | D7: Calculates the average based on one condition | E7: Rooms_Clean
A8: 7 | B8: COUNTIFS | C8: Logical | D8: Counts cells that meet multiple conditions | E8: Rooms_Clean
A9: 8 | B9: SUMIFS | C9: Math & Statistical | D9: Adds values that meet multiple conditions | E9: Rooms_Clean
A10: 9 | B10: IF | C10: Logical | D10: Returns a result based on a condition | E10: Rooms_Clean
A11: 10 | B11: AND | C11: Logical | D11: Checks whether all specified conditions are TRUE | E11: Rooms_Clean
A12: 11 | B12: OR | C12: Logical | D12: Checks whether at least one specified condition is TRUE | E12: Rooms_Clean
A13: 12 | B13: IFERROR | C13: Logical | D13: Returns a custom value when a formula produces an error | E13: Practice/ Room_Clean
... A15: 14 | B15: VLOOKUP | C15: Lookup & Reference | D15: Searches vertically and returns matching information | E15: Bookings_Clean

Sheet Services _Clean
A1: service_id | B1: service_name | C1: service_price
A2: 1 | B2: Breakfast | C2: 300
A3: 2 | B3: Lunch | C3: 500
A4: 3 | B4: Dinner | C4: 600
A5: 4 | B5: Laundry | C5: 200
A6: 5 | B6: Spa | C6: 1500
A7: 6 | B7: Airport Pickup | C7: 1000
A8: 7 | B8: Room Cleaning | C8: 150
A9: 8 | B9: Gym Access | C9: 250
A10: 9 | B10: Extra Bed | C10: 800
A11: 10 | B11: Swimming Pool | C11: 400
A12: 11 | B12: Welcome Drink | C12: 120
A13: 12 | B13: Room Service | C13: 250
... A31: 30 | B31: Business Center | C31: 800

Sheet Payments_Clean
A1: payment_id | B1: booking_id | C1: payment_date | D1: amount | E1: payment_method | F1: payment_status
A2: 1 | B2: 1 | C2: 46296 | D2: 3000 | E2: UPI | F2: Completed
A3: 2 | B3: 2 | C3: 46297 | D3: 7500 | E3: Card | F3: Completed
A4: 3 | B4: 3 | C4: 46305 | D4: 3000 | E4: Cash | F4: Completed
A5: 4 | B5: 4 | C5: 46309 | D5: 12000 | E5: UPI | F5: Completed
A6: 5 | B6: 5 | C6: 46310 | D6: 7500 | E6: Card | F6: Completed
A7: 6 | B7: 6 | C7: 46311 | D7: 19500 | E7: UPI | F7: Completed
A8: 7 | B8: 7 | C8: 46312 | D8: 0 | E8: Cash | F8: Refunded
A9: 8 | B9: 8 | C9: 46313 | D9: 8400 | E9: Card | F9: Pending
A10: 9 | B10: 9 | C10: 46314 | D10: 19500 | E10: UPI | F10: Completed
A11: 10 | B11: 10 | C11: 46315 | D11: 12600 | E11: Cash | F11: Pending
A12: 11 | B12: 11 | C12: 46327 | D12: 3200 | E12: UPI | F12: Completed
A13: 12 | B13: 12 | C13: 46328 | D13: 8100 | E13: Card | F13: Pending
... A151: 150 | B151: 150 | C151: 46461 | D151: 0 | E151: UPI | F151: Refunded

Sheet Bookings_Clean
A1: booking_id | B1: guest_id | C1: room_id | D1: check_in_date | E1: check_out_date | F1: booking_status | G1: Room Type Lookup | H1: Guest Name Lookup | I1: Room Type Lookup2 | J1: Guest City Lookup
A2: 1 | B2: 1 | C2: 1 | D2: 46296 | E2: 46298 | F2: Checked-Out | G2: =_xlfn.XLOOKUP(C2,Rooms_Clean!$A$2:$A$51,Rooms_Clean!$C$2:$C$51,"Not Found") -> Single | H2: =_xlfn.XLOOKUP(B2,Guests_Clean!$A$2:$A$101,Guests_Clean!$B$2:$B$101) -> Rakesh Bhosle | I2: =VLOOKUP(bookings10[[#This Row],[room_id]],rooms9[[room_id]:[room_type]],3,0) -> Single | J2: =VLOOKUP(bookings10[[#This Row],[guest_id]],guests8[[guest_id]:[city]],5,0) -> pune
A3: 2 | B3: 2 | C3: 3 | D3: 46297 | E3: 46300 | F3: Checked-Out | G3: =_xlfn.XLOOKUP(C3,Rooms_Clean!$A$2:$A$51,Rooms_Clean!$C$2:$C$51,"Not Found") -> Double | H3: =_xlfn.XLOOKUP(B3,Guests_Clean!$A$2:$A$101,Guests_Clean!$B$2:$B$101) -> Priya Sharma | I3: =VLOOKUP(bookings10[[#This Row],[room_id]],rooms9[[room_id]:[room_type]],3,0) -> Double | J3: =VLOOKUP(bookings10[[#This Row],[guest_id]],guests8[[guest_id]:[city]],5,0) -> Mumbai
A4: 3 | B4: 3 | C4: 2 | D4: 46305 | E4: 46308 | F4: Checked-Out | G4: =_xlfn.XLOOKUP(C4,Rooms_Clean!$A$2:$A$51,Rooms_Clean!$C$2:$C$51,"Not Found") -> Single | H4: =_xlfn.XLOOKUP(B4,Guests_Clean!$A$2:$A$101,Guests_Clean!$B$2:$B$101) -> Amit Patil | I4: =VLOOKUP(bookings10[[#This Row],[room_id]],rooms9[[room_id]:[room_type]],3,0) -> Single | J4: =VLOOKUP(bookings10[[#This Row],[guest_id]],guests8[[guest_id]:[city]],5,0) -> Pune
A5: 4 | B5: 4 | C5: 5 | D5: 46309 | E5: 46312 | F5: Confirmed | G5: =_xlfn.XLOOKUP(C5,Rooms_Clean!$A$2:$A$51,Rooms_Clean!$C$2:$C$51,"Not Found") -> Deluxe | H5: =_xlfn.XLOOKUP(B5,Guests_Clean!$A$2:$A$101,Guests_Clean!$B$2:$B$101) -> Sneha Joshi | I5: =VLOOKUP(bookings10[[#This Row],[room_id]],rooms9[[room_id]:[room_type]],3,0) -> Deluxe | J5: =VLOOKUP(bookings10[[#This Row],[guest_id]],guests8[[guest_id]:[city]],5,0) -> Nashik
A6: 5 | B6: 5 | C6: 4 | D6: 46310 | E6: 46313 | F6: Confirmed | G6: =_xlfn.XLOOKUP(C6,Rooms_Clean!$A$2:$A$51,Rooms_Clean!$C$2:$C$51,"Not Found") -> Double | H6: =_xlfn.XLOOKUP(B6,Guests_Clean!$A$2:$A$101,Guests_Clean!$B$2:$B$101) -> Rahul Deshmukh | I6: =VLOOKUP(bookings10[[#This Row],[room_id]],rooms9[[room_id]:[room_type]],3,0) -> Double | J6: =VLOOKUP(bookings10[[#This Row],[guest_id]],guests8[[guest_id]:[city]],5,0) -> Pune
A7: 6 | B7: 6 | C7: 7 | D7: 46311 | E7: 46314 | F7: Confirmed | G7: =_xlfn.XLOOKUP(C7,Rooms_Clean!$A$2:$A$51,Rooms_Clean!$C$2:$C$51,"Not Found") -> Suite | H7: =_xlfn.XLOOKUP(B7,Guests_Clean!$A$2:$A$101,Guests_Clean!$B$2:$B$101) -> Neha Kulkarni | I7: =VLOOKUP(bookings10[[#This Row],[room_id]],rooms9[[room_id]:[room_type]],3,0) -> Suite | J7: =VLOOKUP(bookings10[[#This Row],[guest_id]],guests8[[guest_id]:[city]],5,0) -> Nagpur
A8: 7 | B8: 7 | C8: 6 | D8: 46312 | E8: 46315 | F8: Cancelled | G8: =_xlfn.XLOOKUP(C8,Rooms_Clean!$A$2:$A$51,Rooms_Clean!$C$2:$C$51,"Not Found") -> Deluxe | H8: =_xlfn.XLOOKUP(B8,Guests_Clean!$A$2:$A$101,Guests_Clean!$B$2:$B$101) -> Karan Shah | I8: =VLOOKUP(bookings10[[#This Row],[room_id]],rooms9[[room_id]:[room_type]],3,0) -> Deluxe | J8: =VLOOKUP(bookings10[[#This Row],[guest_id]],guests8[[guest_id]:[city]],5,0) -> Mumbai
A9: 8 | B9: 8 | C9: 9 | D9: 46313 | E9: 46316 | F9: Confirmed | G9: =_xlfn.XLOOKUP(C9,Rooms_Clean!$A$2:$A$51,Rooms_Clean!$C$2:$C$51,"Not Found") -> Double | H9: =_xlfn.XLOOKUP(B9,Guests_Clean!$A$2:$A$101,Guests_Clean!$B$2:$B$101) -> Pooja More | I9: =VLOOKUP(bookings10[[#This Row],[room_id]],rooms9[[room_id]:[room_type]],3,0) -> Double | J9: =VLOOKUP(bookings10[[#This Row],[guest_id]],guests8[[guest_id]:[city]],5,0) -> Kolhapur
A10: 9 | B10: 9 | C10: 8 | D10: 46314 | E10: 46317 | F10: Confirmed | G10: =_xlfn.XLOOKUP(C10,Rooms_Clean!$A$2:$A$51,Rooms_Clean!$C$2:$C$51,"Not Found") -> Suite | H10: =_xlfn.XLOOKUP(B10,Guests_Clean!$A$2:$A$101,Guests_Clean!$B$2:$B$101) -> Sahil Pawar | I10: =VLOOKUP(bookings10[[#This Row],[room_id]],rooms9[[room_id]:[room_type]],3,0) -> Suite | J10: =VLOOKUP(bookings10[[#This Row],[guest_id]],guests8[[guest_id]:[city]],5,0) -> Pune
A11: 10 | B11: 10 | C11: 10 | D11: 46315 | E11: 46318 | F11: Confirmed | G11: =_xlfn.XLOOKUP(C11,Rooms_Clean!$A$2:$A$51,Rooms_Clean!$C$2:$C$51,"Not Found") -> Deluxe | H11: =_xlfn.XLOOKUP(B11,Guests_Clean!$A$2:$A$101,Guests_Clean!$B$2:$B$101) -> Isha Mehta | I11: =VLOOKUP(bookings10[[#This Row],[room_id]],rooms9[[room_id]:[room_type]],3,0) -> Deluxe | J11: =VLOOKUP(bookings10[[#This Row],[guest_id]],guests8[[guest_id]:[city]],5,0) -> Nashik
A12: 11 | B12: 11 | C12: 11 | D12: 46327 | E12: 46329 | F12: Confirmed | G12: =_xlfn.XLOOKUP(C12,Rooms_Clean!$A$2:$A$51,Rooms_Clean!$C$2:$C$51,"Not Found") -> Single | H12: =_xlfn.XLOOKUP(B12,Guests_Clean!$A$2:$A$101,Guests_Clean!$B$2:$B$101) -> Aarav Deshmukh | I12: =VLOOKUP(bookings10[[#This Row],[room_id]],rooms9[[room_id]:[room_type]],3,0) -> Single | J12: =VLOOKUP(bookings10[[#This Row],[guest_id]],guests8[[guest_id]:[city]],5,0) -> Pune
A13: 12 | B13: 12 | C13: 12 | D13: 46328 | E13: 46331 | F13: Confirmed | G13: =_xlfn.XLOOKUP(C13,Rooms_Clean!$A$2:$A$51,Rooms_Clean!$C$2:$C$51,"Not Found") -> Double | H13: =_xlfn.XLOOKUP(B13,Guests_Clean!$A$2:$A$101,Guests_Clean!$B$2:$B$101) -> Sneha Joshi | I13: =VLOOKUP(bookings10[[#This Row],[room_id]],rooms9[[room_id]:[room_type]],3,0) -> Double | J13: =VLOOKUP(bookings10[[#This Row],[guest_id]],guests8[[guest_id]:[city]],5,0) -> Mumbai
... A151: 150 | B151: 50 | C151: 50 | D151: 46461 | E151: 46463 | F151: Cancelled | G151: =_xlfn.XLOOKUP(C151,Rooms_Clean!$A$2:$A$51,Rooms_Clean!$C$2:$C$51,"Not Found") -> Double | H151: =_xlfn.XLOOKUP(B151,Guests_Clean!$A$2:$A$101,Guests_Clean!$B$2:$B$101) -> Madhura Shinde | I151: =VLOOKUP(bookings10[[#This Row],[room_id]],rooms9[[room_id]:[room_type]],3,0) -> Double | J151: =VLOOKUP(bookings10[[#This Row],[guest_id]],guests8[[guest_id]:[city]],5,0) -> Mumbai

Sheet Rooms_Clean
A1: room_id | B1: room_number | C1: room_type | D1: price_per_night | E1: room_status | F1: Description | G1: Room Available Statues | H1: Room Price Category >3K = Premium
A2: 1 | B2: 101 | C2: Single | D2: 1500 | E2: Available | F2: Not Provided | G2: =IF(rooms9[[#This Row],[room_status]]="Available","Vecant","Not Available") -> Vecant | H2: =IF(rooms9[[#This Row],[price_per_night]]>3000,"Premium","Regular") -> Regular
A3: 2 | B3: 102 | C3: Single | D3: 1500 | E3: Occupied | F3: Not Provided | G3: =IF(rooms9[[#This Row],[room_status]]="Available","Vecant","Not Available") -> Not Available | H3: =IF(rooms9[[#This Row],[price_per_night]]>3000,"Premium","Regular") -> Regular
A4: 3 | B4: 103 | C4: Double | D4: 2500 | E4: Available | F4: Double room with AC | G4: =IF(rooms9[[#This Row],[room_status]]="Available","Vecant","Not Available") -> Vecant | H4: =IF(rooms9[[#This Row],[price_per_night]]>3000,"Premium","Regular") -> Regular
A5: 4 | B5: 104 | C5: Double | D5: 2500 | E5: Occupied | F5: Not Provided | G5: =IF(rooms9[[#This Row],[room_status]]="Available","Vecant","Not Available") -> Not Available | H5: =IF(rooms9[[#This Row],[price_per_night]]>3000,"Premium","Regular") -> Regular | K5: Count Room Price Rows | N5: Count Available Rooms | P5: Count Occupied Rooms
A6: 5 | B6: 201 | C6: Deluxe | D6: 4000 | E6: Available | F6: Not Provided | G6: =IF(rooms9[[#This Row],[room_status]]="Available","Vecant","Not Available") -> Vecant | H6: =IF(rooms9[[#This Row],[price_per_night]]>3000,"Premium","Regular") -> Premium | K6: =COUNT(rooms9[price_per_night]) -> 50 | N6: =COUNTIF(rooms9[room_status],"Available") -> 35 | P6: =COUNTIF(rooms9[room_status],"Occupied") -> 10
A7: 6 | B7: 202 | C7: Deluxe | D7: 4500 | E7: Maintenance | F7: Not Provided | G7: =IF(rooms9[[#This Row],[room_status]]="Available","Vecant","Not Available") -> Not Available | H7: =IF(rooms9[[#This Row],[price_per_night]]>3000,"Premium","Regular") -> Premium
A8: 7 | B8: 203 | C8: Suite | D8: 6500 | E8: Available | F8: Not Provided | G8: =IF(rooms9[[#This Row],[room_status]]="Available","Vecant","Not Available") -> Vecant | H8: =IF(rooms9[[#This Row],[price_per_night]]>3000,"Premium","Regular") -> Premium
A9: 8 | B9: 204 | C9: Suite | D9: 6500 | E9: Occupied | F9: Not Provided | G9: =IF(rooms9[[#This Row],[room_status]]="Available","Vecant","Not Available") -> Not Available | H9: =IF(rooms9[[#This Row],[price_per_night]]>3000,"Premium","Regular") -> Premium
A10: 9 | B10: 301 | C10: Double | D10: 2800 | E10: Available | F10: Not Provided | G10: =IF(rooms9[[#This Row],[room_status]]="Available","Vecant","Not Available") -> Vecant | H10: =IF(rooms9[[#This Row],[price_per_night]]>3000,"Premium","Regular") -> Regular | K10: Total Room Price | N10: Total Price Of Single Rooms | P10: Total Price Of Double Rooms
A11: 10 | B11: 302 | C11: Deluxe | D11: 4200 | E11: Available | F11: Not Provided | G11: =IF(rooms9[[#This Row],[room_status]]="Available","Vecant","Not Available") -> Vecant | H11: =IF(rooms9[[#This Row],[price_per_night]]>3000,"Premium","Regular") -> Premium | K11: =SUM(rooms9[price_per_night]) -> 198200 | N11: =SUMIF(rooms9[room_type],"Single",rooms9[price_per_night]) -> 19900 | P11: =SUMIF(rooms9[room_type],"Double",rooms9[price_per_night]) -> 43300
A12: 11 | B12: 303 | C12: Single | D12: 1600 | E12: Available | F12: Not Provided | G12: =IF(rooms9[[#This Row],[room_status]]="Available","Vecant","Not Available") -> Vecant | H12: =IF(rooms9[[#This Row],[price_per_night]]>3000,"Premium","Regular") -> Regular
A13: 12 | B13: 304 | C13: Double | D13: 2700 | E13: Available | F13: Not Provided | G13: =IF(rooms9[[#This Row],[room_status]]="Available","Vecant","Not Available") -> Vecant | H13: =IF(rooms9[[#This Row],[price_per_night]]>3000,"Premium","Regular") -> Regular
A14: 13 | B14: 305 | C14: Deluxe | D14: 4300 | E14: Occupied | F14: Not Provided | G14: =IF(rooms9[[#This Row],[room_status]]="Available","Vecant","Not Available") -> Not Available | H14: =IF(rooms9[[#This Row],[price_per_night]]>3000,"Premium","Regular") -> Premium | K14: Average Of Room Price | N14: Average Of Single Rooms | P14: Average Of Double Rooms
A15: 14 | B15: 306 | C15: Suite | D15: 6800 | E15: Available | F15: Not Provided | G15: =IF(rooms9[[#This Row],[room_status]]="Available","Vecant","Not Available") -> Vecant | H15: =IF(rooms9[[#This Row],[price_per_night]]>3000,"Premium","Regular") -> Premium | K15: =AVERAGE(rooms9[price_per_night]) -> 3964 | N15: =AVERAGEIF(rooms9[room_type],"Single",D2:D51) -> 1658.3333 | P15: =AVERAGEIF(rooms9[room_type],"Double",rooms9[price_per_night]) -> 2886.6667
A16: 15 | B16: 307 | C16: Double | D16: 2800 | E16: Maintenance | F16: Not Provided | G16: =IF(rooms9[[#This Row],[room_status]]="Available","Vecant","Not Available") -> Not Available | H16: =IF(rooms9[[#This Row],[price_per_night]]>3000,"Premium","Regular") -> Regular
A17: 16 | B17: 308 | C17: Single | D17: 1600 | E17: Available | F17: Not Provided | G17: =IF(rooms9[[#This Row],[room_status]]="Available","Vecant","Not Available") -> Vecant | H17: =IF(rooms9[[#This Row],[price_per_night]]>3000,"Premium","Regular") -> Regular
A18: 17 | B18: 309 | C18: Single | D18: 1700 | E18: Available | F18: Not Provided | G18: =IF(rooms9[[#This Row],[room_status]]="Available","Vecant","Not Available") -> Vecant | H18: =IF(rooms9[[#This Row],[price_per_night]]>3000,"Premium","Regular") -> Regular | K18: Count Price Of Occupied Double Rooms | N18: Count Available Single Rooms | P18: Count Occupied Double Rooms
A19: 18 | B19: 310 | C19: Double | D19: 2700 | E19: Available | F19: Not Provided | G19: =IF(rooms9[[#This Row],[room_status]]="Available","Vecant","Not Available") -> Vecant | H19: =IF(rooms9[[#This Row],[price_per_night]]>3000,"Premium","Regular") -> Regular | K19: =COUNTIFS(rooms9[room_type],"Single",rooms9[room_status],"Occupied") -> 2 | N19: =COUNTIFS(rooms9[room_type],"Single",rooms9[room_status],"Available") -> 9 | P19: =COUNTIFS(rooms9[room_type],"Double",rooms9[room_status],"Occupied") -> 3
A20: 19 | B20: 311 | C20: Double | D20: 2800 | E20: Occupied | F20: Not Provided | G20: =IF(rooms9[[#This Row],[room_status]]="Available","Vecant","Not Available") -> Not Available | H20: =IF(rooms9[[#This Row],[price_per_night]]>3000,"Premium","Regular") -> Regular
A21: 20 | B21: 312 | C21: Deluxe | D21: 4300 | E21: Available | F21: Not Provided | G21: =IF(rooms9[[#This Row],[room_status]]="Available","Vecant","Not Available") -> Vecant | H21: =IF(rooms9[[#This Row],[price_per_night]]>3000,"Premium","Regular") -> Premium
A22: 21 | B22: 313 | C22: Suite | D22: 6800 | E22: Available | F22: Not Provided | G22: =IF(rooms9[[#This Row],[room_status]]="Available","Vecant","Not Available") -> Vecant | H22: =IF(rooms9[[#This Row],[price_per_night]]>3000,"Premium","Regular") -> Premium | N22: Total Price Of Available Single Rooms | P22: Total Price Of Occupied Double Rooms
A23: 22 | B23: 314 | C23: Single | D23: 1500 | E23: Maintenance | F23: Not Provided | G23: =IF(rooms9[[#This Row],[room_status]]="Available","Vecant","Not Available") -> Not Available | H23: =IF(rooms9[[#This Row],[price_per_night]]>3000,"Premium","Regular") -> Regular | N23: =SUMIFS(rooms9[price_per_night],rooms9[room_type],"Single",rooms9[room_status],"Available") -> 15150 | P23: =SUMIFS(rooms9[price_per_night],rooms9[room_type],"Double",rooms9[room_status],"Occupied") -> 8400
A24: 23 | B24: 315 | C24: Double | D24: 2900 | E24: Available | F24: Not Provided | G24: =IF(rooms9[[#This Row],[room_status]]="Available","Vecant","Not Available") -> Vecant | H24: =IF(rooms9[[#This Row],[price_per_night]]>3000,"Premium","Regular") -> Regular
A25: 24 | B25: 316 | C25: Deluxe | D25: 4500 | E25: Occupied | F25: Not Provided | G25: =IF(rooms9[[#This Row],[room_status]]="Available","Vecant","Not Available") -> Not Available | H25: =IF(rooms9[[#This Row],[price_per_night]]>3000,"Premium","Regular") -> Premium
A26: 25 | B26: 317 | C26: Suite | D26: 7000 | E26: Available | F26: Not Provided | G26: =IF(rooms9[[#This Row],[room_status]]="Available","Vecant","Not Available") -> Vecant | H26: =IF(rooms9[[#This Row],[price_per_night]]>3000,"Premium","Regular") -> Premium | K26: Check Room Eligibility | M26: IFERROR Practice
A27: 26 | B27: 318 | C27: Single | D27: 1650 | E27: Available | F27: Not Provided | G27: =IF(rooms9[[#This Row],[room_status]]="Available","Vecant","Not Available") -> Vecant | H27: =IF(rooms9[[#This Row],[price_per_night]]>3000,"Premium","Regular") -> Regular | K27: =IF(AND(D2>3000,E2="Available"),"Eligible","Not Eligible" ) -> Not Eligible | M27: =IFERROR(1/0,"Invalid") -> Invalid
A28: 27 | B28: 319 | C28: Double | D28: 2750 | E28: Available | F28: Not Provided | G28: =IF(rooms9[[#This Row],[room_status]]="Available","Vecant","Not Available") -> Vecant | H28: =IF(rooms9[[#This Row],[price_per_night]]>3000,"Premium","Regular") -> Regular
A29: 28 | B29: 320 | C29: Deluxe | D29: 4400 | E29: Available | F29: Not Provided | G29: =IF(rooms9[[#This Row],[room_status]]="Available","Vecant","Not Available") -> Vecant | H29: =IF(rooms9[[#This Row],[price_per_night]]>3000,"Premium","Regular") -> Premium | K29: Room Priority Check
A30: 29 | B30: 321 | C30: Suite | D30: 7200 | E30: Occupied | F30: Not Provided | G30: =IF(rooms9[[#This Row],[room_status]]="Available","Vecant","Not Available") -> Not Available | H30: =IF(rooms9[[#This Row],[price_per_night]]>3000,"Premium","Regular") -> Premium | K30: =IF(OR(D7>4000,E6="Maintenance"),"Priority","Normal") -> Priority
A31: 30 | B31: 322 | C31: Single | D31: 1550 | E31: Available | F31: Not Provided | G31: =IF(rooms9[[#This Row],[room_status]]="Available","Vecant","Not Available") -> Vecant | H31: =IF(rooms9[[#This Row],[price_per_night]]>3000,"Premium","Regular") -> Regular
A32: 31 | B32: 323 | C32: Double | D32: 2850 | E32: Maintenance | F32: Not Provided | G32: =IF(rooms9[[#This Row],[room_status]]="Available","Vecant","Not Available") -> Not Available | H32: =IF(rooms9[[#This Row],[price_per_night]]>3000,"Premium","Regular") -> Regular
A33: 32 | B33: 324 | C33: Deluxe | D33: 4600 | E33: Available | F33: Not Provided | G33: =IF(rooms9[[#This Row],[room_status]]="Available","Vecant","Not Available") -> Vecant | H33: =IF(rooms9[[#This Row],[price_per_night]]>3000,"Premium","Regular") -> Premium
A34: 33 | B34: 325 | C34: Suite | D34: 7500 | E34: Available | F34: Not Provided | G34: =IF(rooms9[[#This Row],[room_status]]="Available","Vecant","Not Available") -> Vecant | H34: =IF(rooms9[[#This Row],[price_per_night]]>3000,"Premium","Regular") -> Premium
A35: 34 | B35: 326 | C35: Single | D35: 1750 | E35: Occupied | F35: Not Provided | G35: =IF(rooms9[[#This Row],[room_status]]="Available","Vecant","Not Available") -> Not Available | H35: =IF(rooms9[[#This Row],[price_per_night]]>3000,"Premium","Regular") -> Regular
A36: 35 | B36: 327 | C36: Double | D36: 3000 | E36: Available | F36: Not Provided | G36: =IF(rooms9[[#This Row],[room_status]]="Available","Vecant","Not Available") -> Vecant | H36: =IF(rooms9[[#This Row],[price_per_night]]>3000,"Premium","Regular") -> Regular
A37: 36 | B37: 328 | C37: Deluxe | D37: 4700 | E37: Available | F37: Not Provided | G37: =IF(rooms9[[#This Row],[room_status]]="Available","Vecant","Not Available") -> Vecant | H37: =IF(rooms9[[#This Row],[price_per_night]]>3000,"Premium","Regular") -> Premium
A38: 37 | B38: 329 | C38: Suite | D38: 7800 | E38: Available | F38: Not Provided | G38: =IF(rooms9[[#This Row],[room_status]]="Available","Vecant","Not Available") -> Vecant | H38: =IF(rooms9[[#This Row],[price_per_night]]>3000,"Premium","Regular") -> Premium
A39: 38 | B39: 330 | C39: Single | D39: 1800 | E39: Available | F39: Not Provided | G39: =IF(rooms9[[#This Row],[room_status]]="Available","Vecant","Not Available") -> Vecant | H39: =IF(rooms9[[#This Row],[price_per_night]]>3000,"Premium","Regular") -> Regular
A40: 39 | B40: 331 | C40: Double | D40: 3100 | E40: Occupied | F40: Not Provided | G40: =IF(rooms9[[#This Row],[room_status]]="Available","Vecant","Not Available") -> Not Available | H40: =IF(rooms9[[#This Row],[price_per_night]]>3000,"Premium","Regular") -> Premium
...

Sheet rooms
A1: room_id | B1: room_number | C1: room_type | D1: price_per_night | E1: room_status | F1: Description
A2: 1 | B2: 101 | C2: Single | D2: 1500 | E2: Available
A3: 2 | B3: 102 | C3: Single | D3: 1500 | E3: Occupied
A4: 3 | B4: 103 | C4: Double | D4: 2500 | E4: Available | F4: Double room with AC
A5: 4 | B5: 104 | C5: Double | D5: 2500 | E5: Occupied
A6: 5 | B6: 201 | C6: Deluxe | D6: 4000 | E6: Available
A7: 6 | B7: 202 | C7: Deluxe | D7: 4500 | E7: Maintenance
A8: 7 | B8: 203 | C8: Suite | D8: 6500 | E8: Available
A9: 8 | B9: 204 | C9: Suite | D9: 6500 | E9: Occupied
A10: 9 | B10: 301 | C10: Double | D10: 2800 | E10: Available
A11: 10 | B11: 302 | C11: Deluxe | D11: 4200 | E11: Available
A12: 11 | B12: 303 | C12: Single | D12: 1600 | E12: Available
A13: 12 | B13: 304 | C13: Double | D13: 2700 | E13: Available
A14: 13 | B14: 305 | C14: Deluxe | D14: 4300 | E14: Occupied
A15: 14 | B15: 306 | C15: Suite | D15: 6800 | E15: Available
A16: 15 | B16: 307 | C16: Double | D16: 2800 | E16: Maintenance
... A51: 50 | B51: 342 | C51: Double | D51: 3400 | E51: Available

Sheet Guests_Clean
A1: guest_id | B1: guest_name | C1: phone | D1: email | E1: city | F1: created_at | G1: Gender
A2: 1 | B2: Rakesh Bhosle | C2: 7823464181 | D2: RakeshB@gmail.com | E2: pune | F2: 45830.428 | G2: Not Provided
A3: 2 | B3: Priya Sharma | C3: 9823012345 | D3: priya@gmail.com | E3: Mumbai | F3: 45831.396 | G3: Not Provided
A4: 3 | B4: Amit Patil | C4: 9765012345 | D4: amit@gmail.com | E4: Pune | F4: 45832.469 | G4: Male
A5: 4 | B5: Sneha Joshi | C5: 9890012345 | D5: sneha@gmail.com | E5: Nashik | F5: 45833.597 | G5: Not Provided
A6: 5 | B6: Rahul Deshmukh | C6: 9123012345 | D6: rahul@gmail.com | E6: Pune | F6: 45834.698 | G6: Not Provided
A7: 6 | B7: Neha Kulkarni | C7: 9766012345 | D7: neha@gmail.com | E7: Nagpur | F7: 45835.417 | G7: Not Provided
A8: 7 | B8: Karan Shah | C8: 9822012345 | D8: karan@gmail.com | E8: Mumbai | F8: 45836.521 | G8: Not Provided
A9: 8 | B9: Pooja More | C9: 9891012345 | D9: pooja@gmail.com | E9: Kolhapur | F9: 45837.549 | G9: Not Provided
A10: 9 | B10: Sahil Pawar | C10: 9156012345 | D10: sahil@gmail.com | E10: Pune | F10: 45838.708 | G10: Not Provided
A11: 10 | B11: Isha Mehta | C11: 9767012345 | D11: isha@gmail.com | E11: Nashik | F11: 45839.365 | G11: Not Provided
A12: 11 | B12: Aarav Deshmukh | C12: 9876501234 | D12: aarav@example.com | E12: Pune | F12: 45840.375 | G12: Male
A13: 12 | B13: Sneha Joshi | C13: 9876501235 | D13: sneha@example.com | E13: Mumbai | F13: 45840.385 | G13: Female
... A36: 35 | B36: Nikhil Patil | C36: 9000000035 | D36: guest35@example.com | E36: Nashik | F36: 45841.521 | G36: Not Provided
A37: 36 | B37: Kavita Shah | C37: 9000000036 | D37: guest36@example.com | E37: Nagpur | F37: 45841.531 | G37: Female | J37: =COUNTBLANK(guests8[Gender]) -> 0
A38: 37 | B38: Sagar Kulkarni | C38: 9000000037 | D38: guest37@example.com | E38: Pune | F38: 45841.542 | G38: Male
A39: 38 | B39: Isha Deshmukh | C39: 9000000038 | D39: guest38@example.com | E39: Mumbai | F39: 45841.552 | G39: Not Provided
A40: 39 | B40: Omkar Jadhav | C40: 9000000039 | D40: guest39@example.com | E40: Nashik | F40: 45841.562 | G40: Female
A41: 40 | B41: Pallavi Sharma | C41: 9000000040 | D41: guest40@example.com | E41: Nagpur | F41: 45841.573 | G41: Not Provided
A42: 41 | B42: Aditya Joshi | C42: 9000000041 | D42: guest41@example.com | E42: Pune | F42: 45841.583 | G42: Male
A43: 42 | B43: Shruti Patil | C43: 9000000042 | D43: guest42@example.com | E43: Mumbai | F43: 45841.594 | G43: Female
A44: 43 | B44: Manoj Kulkarni | C44: 9000000043 | D44: guest43@example.com | E44: Nashik | F44: 45841.604 | G44: Not Provided
A45: 44 | B45: Sayali Deshmukh | C45: 9000000044 | D45: guest44@example.com | E45: Nagpur | F45: 45841.615 | G45: Male
A46: 45 | B46: Varun Shah | C46: 9000000045 | D46: guest45@example.com | E46: Pune | F46: 45841.625 | G46: Not Provided
A47: 46 | B47: Aarti Pawar | C47: 9000000046 | D47: guest46@example.com | E47: Mumbai | F47: 45841.635 | G47: Female
A48: 47 | B48: Prasad More | C48: 9000000047 | D48: guest47@example.com | E48: Nashik | F48: 45841.646 | G48: Male
A49: 48 | B49: Riya Sharma | C49: 9000000048 | D49: guest48@example.com | E49: Nagpur | F49: 45841.656 | G49: Not Provided
... A101: 100 | B101: Manisha Sharma | C101: 9000000100 | D101: guest100@example.com | E101: Nagpur | F101: 45842.573 | G101: Not Provided

Sheet booking_services
A1: booking_service_id | B1: booking_id | C1: service_id | D1: quantity
A2: 1 | B2: 1 | C2: 1 | D2: 2
A3: 2 | B3: 1 | C3: 4 | D3: 1
A4: 3 | B4: 2 | C4: 2 | D4: 2
A5: 4 | B5: 2 | C5: 3 | D5: 2
A6: 5 | B6: 3 | C6: 1 | D6: 1
A7: 6 | B7: 4 | C7: 5 | D7: 2
A8: 7 | B8: 4 | C8: 7 | D8: 1
A9: 8 | B9: 5 | C9: 6 | D9: 1
A10: 9 | B10: 6 | C10: 8 | D10: 2
A11: 10 | B11: 8 | C11: 9 | D11: 1
A12: 11 | B12: 9 | C12: 10 | D12: 2
A13: 12 | B13: 10 | C13: 3 | D13: 3
... A201: 200 | B201: 60 | C201: 21 | D201: 3

Sheet services
A1: service_id | B1: service_name | C1: service_price
A2: 1 | B2: Breakfast | C2: 300
A3: 2 | B3: Lunch | C3: 500
A4: 3 | B4: Dinner | C4: 600
A5: 4 | B5: Laundry | C5: 200
A6: 5 | B6: Spa | C6: 1500
A7: 6 | B7: Airport Pickup | C7: 1000
A8: 7 | B8: Room Cleaning | C8: 150
A9: 8 | B9: Gym Access | C9: 250
A10: 9 | B10: Extra Bed | C10: 800
A11: 10 | B11: Swimming Pool | C11: 400
A12: 11 | B12: Welcome Drink | C12: 120
A13: 12 | B13: Room Service | C13: 250
... A31: 30 | B31: Business Center | C31: 800

Sheet payments
A1: payment_id | B1: booking_id | C1: payment_date | D1: amount | E1: payment_method | F1: payment_status
A2: 1 | B2: 1 | C2: 46296 | D2: 3000 | E2: UPI | F2: Completed
A3: 2 | B3: 2 | C3: 46297 | D3: 7500 | E3: Card | F3: Completed
A4: 3 | B4: 3 | C4: 46305 | D4: 3000 | E4: Cash | F4: Completed
A5: 4 | B5: 4 | C5: 46309 | D5: 12000 | E5: UPI | F5: Completed
A6: 5 | B6: 5 | C6: 46310 | D6: 7500 | E6: Card | F6: Completed
A7: 6 | B7: 6 | C7: 46311 | D7: 19500 | E7: UPI | F7: Completed
A8: 7 | B8: 7 | C8: 46312 | D8: 0 | E8: Cash | F8: Refunded
A9: 8 | B9: 8 | C9: 46313 | D9: 8400 | E9: Card | F9: Pending
A10: 9 | B10: 9 | C10: 46314 | D10: 19500 | E10: UPI | F10: Completed
A11: 10 | B11: 10 | C11: 46315 | D11: 12600 | E11: Cash | F11: Pending
A12: 11 | B12: 11 | C12: 46327 | D12: 3200 | E12: UPI | F12: Completed
A13: 12 | B13: 12 | C13: 46328 | D13: 8100 | E13: Card | F13: Pending
... A151: 150 | B151: 150 | C151: 46461 | D151: 0 | E151: UPI | F151: Refunded

Sheet bookings
A1: booking_id | B1: guest_id | C1: room_id | D1: check_in_date | E1: check_out_date | F1: booking_status
A2: 1 | B2: 1 | C2: 1 | D2: 46296 | E2: 46298 | F2: Checked-Out
A3: 2 | B3: 2 | C3: 3 | D3: 46297 | E3: 46300 | F3: Checked-Out
A4: 3 | B4: 3 | C4: 2 | D4: 46305 | E4: 46308 | F4: Checked-Out
A5: 4 | B5: 4 | C5: 5 | D5: 46309 | E5: 46312 | F5: Confirmed
A6: 5 | B6: 5 | C6: 4 | D6: 46310 | E6: 46313 | F6: Confirmed
A7: 6 | B7: 6 | C7: 7 | D7: 46311 | E7: 46314 | F7: Confirmed
A8: 7 | B8: 7 | C8: 6 | D8: 46312 | E8: 46315 | F8: Cancelled
A9: 8 | B9: 8 | C9: 9 | D9: 46313 | E9: 46316 | F9: Confirmed
A10: 9 | B10: 9 | C10: 8 | D10: 46314 | E10: 46317 | F10: Confirmed
A11: 10 | B11: 10 | C11: 10 | D11: 46315 | E11: 46318 | F11: Confirmed
A12: 11 | B12: 11 | C12: 11 | D12: 46327 | E12: 46329 | F12: Confirmed
A13: 12 | B13: 12 | C13: 12 | D13: 46328 | E13: 46331 | F13: Confirmed
... A151: 150 | B151: 50 | C151: 50 | D151: 46461 | E151: 46463 | F151: Cancelled

Sheet guests
A1: guest_id | B1: guest_name | C1: phone | D1: email | E1: city | F1: created_at | G1: Gender
A2: 1 | B2: Rakesh Bhosle | C2: 7823464181 | D2: RakeshB@gmail.com | E2: pune | F2: 45830.428
A3: 2 | B3: Priya Sharma | C3: 9823012345 | D3: priya@gmail.com | E3: Mumbai | F3: 45831.396
A4: 3 | B4: Amit Patil | C4: 9765012345 | D4: amit@gmail.com | E4: Pune | F4: 45832.469 | G4: Male
A5: 4 | B5: Sneha Joshi | C5: 9890012345 | D5: sneha@gmail.com | E5: Nashik | F5: 45833.597
A6: 5 | B6: Rahul Deshmukh | C6: 9123012345 | D6: rahul@gmail.com | E6: Pune | F6: 45834.698
A7: 6 | B7: Neha Kulkarni | C7: 9766012345 | D7: neha@gmail.com | E7: Nagpur | F7: 45835.417
A8: 7 | B8: Karan Shah | C8: 9822012345 | D8: karan@gmail.com | E8: Mumbai | F8: 45836.521
A9: 8 | B9: Pooja More | C9: 9891012345 | D9: pooja@gmail.com | E9: Kolhapur | F9: 45837.549
A10: 9 | B10: Sahil Pawar | C10: 9156012345 | D10: sahil@gmail.com | E10: Pune | F10: 45838.708
A11: 10 | B11: Isha Mehta | C11: 9767012345 | D11: isha@gmail.com | E11: Nashik | F11: 45839.365
A12: 11 | B12: Aarav Deshmukh | C12: 9876501234 | D12: aarav@example.com | E12: Pune | F12: 45840.375 | G12: Male
A13: 12 | B13: Sneha Joshi | C13: 9876501235 | D13: sneha@example.com | E13: Mumbai | F13: 45840.385 | G13: Female
A14: 13 | B14: Rohan Patil | C14: 9876501236 | D14: rohan@example.com | E14: Nashik | F14: 45840.396 | G14: Male
A15: 14 | B15: Ananya Shah | C15: 9876501237 | D15: ananya@example.com | E15: Nagpur | F15: 45840.406 | G15: Female
A16: 15 | B16: Vedant Kulkarni | C16: 9876501238 | D16: vedant@example.com | E16: Pune | F16: 45840.417 | G16: Male
A17: 16 | B17: Mira Pawar | C17: 9876501239 | D17: mira@example.com | E17: Kolhapur | F17: 45840.427
A18: 17 | B18: Aditya More | C18: 9876501240 | D18: aditya@example.com | E18: Mumbai | F18: 45840.438
A19: 18 | B19: Ira Desai | C19: 9876501241 | D19: ira@example.com | E19: Nashik | F19: 45840.448
A20: 19 | B20: Omkar Jadhav | C20: 9876501242 | D20: omkar@example.com | E20: Pune | F20: 45840.458
A21: 20 | B21: Sana Khan | C21: 9876501243 | D21: sana@example.com | E21: Nagpur | F21: 45840.469
A22: 21 | B22: Rohan Patil | C22: 9000000021 | D22: guest21@example.com | E22: Pune | F22: 45841.375 | G22: Male
A23: 22 | B23: Sneha Kulkarni | C23: 9000000022 | D23: guest22@example.com | E23: Mumbai | F23: 45841.385 | G23: Female
A24: 23 | B24: Amit Sharma | C24: 9000000023 | D24: guest23@example.com | E24: Nashik | F24: 45841.396
A25: 24 | B25: Pooja Deshmukh | C25: 9000000024 | D25: guest24@example.com | E25: Nagpur | F25: 45841.406 | G25: Male
A26: 25 | B26: Karan Joshi | C26: 9000000025 | D26: guest25@example.com | E26: Pune | F26: 45841.417
A27: 26 | B27: Priya Shah | C27: 9000000026 | D27: guest26@example.com | E27: Mumbai | F27: 45841.427 | G27: Female
A28: 27 | B28: Rahul More | C28: 9000000027 | D28: guest27@example.com | E28: Nashik | F28: 45841.438 | G28: Male
A29: 28 | B29: Neha Pawar | C29: 9000000028 | D29: guest28@example.com | E29: Nagpur | F29: 45841.448
A30: 29 | B30: Sanket Jadhav | C30: 9000000029 | D30: guest29@example.com | E30: Pune | F30: 45841.458 | G30: Female
A31: 30 | B31: Anjali Patil | C31: 9000000030 | D31: guest30@example.com | E31: Mumbai | F31: 45841.469
A32: 31 | B32: Vikas Shinde | C32: 9000000031 | D32: guest31@example.com | E32: Nashik | F32: 45841.479 | G32: Male
A33: 32 | B33: Meera Joshi | C33: 9000000032 | D33: guest32@example.com | E33: Nagpur | F33: 45841.49 | G33: Female
A34: 33 | B34: Akash Pawar | C34: 9000000033 | D34: guest33@example.com | E34: Pune | F34: 45841.5
A35: 34 | B35: Rutuja More | C35: 9000000034 | D35: guest34@example.com | E35: Mumbai | F35: 45841.51 | G35: Male
A36: 35 | B36: Nikhil Patil | C36: 9000000035 | D36: guest35@example.com | E36: Nashik | F36: 45841.521
A37: 36 | B37: Kavita Shah | C37: 9000000036 | D37: guest36@example.com | E37: Nagpur | F37: 45841.531 | G37: Female | J37: =COUNTBLANK(guests[Gender]) -> 46
A38: 37 | B38: Sagar Kulkarni | C38: 9000000037 | D38: guest37@example.com | E38: Pune | F38: 45841.542 | G38: Male
A39: 38 | B39: Isha Deshmukh | C39: 9000000038 | D39: guest38@example.com | E39: Mumbai | F39: 45841.552
A40: 39 | B40: Omkar Jadhav | C40: 9000000039 | D40: guest39@example.com | E40: Nashik | F40: 45841.562 | G40: Female
...

Sheet Sheet1
